Workbook
Name 신청내역: '근태신청관리 다운로드'!$I:$Y
Name 신청월: '근태신청관리 다운로드'!$B:$B
Name 초과시간: '근태신청관리 다운로드'!$Y:$Y

Sheet 근태신청관리 다운로드
A1: No | B1: 연월구분 | C1: 기간 | D1: 신청일수 | E1: 신청시간 | F1: 사용일수 | G1: 부서 | H1: 직급 | I1: 이름 | J1: ERP사번 | K1: 근태항목 | L1: 근태구분 | M1: 상태 | N1: 종결일자 | O1: 신청내역 | P1: 문서번호 | Q1: 출장지 | R1: 교통수단 | S1: 출장목적 | T1: 비고 | U1: 초과근무일자 | V1: 주차 | W1: 시작시간 | X1: 종료시간 | Y1: 초과시간 | Z1: 초과근무 내역 | AB1: 이메일
A2: =SUBTOTAL(3,$I$2:I2)*1 -> 1 | B2: 25년 1월 | C2: 2025-01-30(08:55) ~ 2025-01-30(14:00) | D2: 1 | E2: 5.10시간 | F2: 0 | G2: AR3팀 | H2: Team Member | I2: 김기연 | J2: 24030401 | K2: 유연근무 | L2: 초과근무 | M2: 결재종결 | N2: 2025-01-31 | O2: 250128-30_AR2팀_김기연_유연근무신청서 (초과근무) | P2: 뉴로핏 주식회사-250131-AR2팀-0003 | T2: nnDet 실험 및 ISC e-poster 확인 | U2: =DATEVALUE(LEFT(C2,10)) -> 45687 | V2: =WEEKNUM(U2,21) -> 5 | W2: =MID(C2,12,5) -> 08:55 | X2: =MID(C2,32,5) -> 14:00 | Y2: =X2-W2 -> 0.21180556 | Z2: =TEXT(U2, "YYYY-MM-DD aaa")&" ("&TEXT(W2, "hh:mm")&"~"&TEXT(X2, "hh:mm")&") : "&IF(MINUTE(Y2)=0, TEXT(Y2, "h시간"), TEXT(Y2, "h시간 m분")) -> 2025-01-30 목 (08:55~14:00) : 5시간 5분 | AB2: =_xlfn.XLOOKUP(I2, 기초데이터!$C$2:$C$305, 기초데이터!$U$2:$U$305) -> kgy@neurophet.com
A3: =SUBTOTAL(3,$I$2:I3)*1 -> 2 | B3: 25년 1월 | C3: 2025-01-30(15:36) ~ 2025-01-30(17:55) | D3: 1 | E3: 2.30시간 | F3: 0 | G3: AR1팀 | H3: Team Member | I3: 조상영 | J3: 23022701 | K3: 유연근무 | L3: 초과근무 | M3: 결재종결 | N3: 2025-02-03 | O3: 20250126, 250128, 250129, 250130 AR1팀 조상영 유연근무 신청서 (초과근무) | P3: 뉴로핏 주식회사-250203-AR1팀-0002 | T3: AQUA AD 3.0 통합 엔진 개발 | U3: =DATEVALUE(LEFT(C3,10)) -> 45687 | V3: =WEEKNUM(U3,21) -> 5 | W3: =MID(C3,12,5) -> 15:36 | X3: =MID(C3,32,5) -> 17:55 | Y3: =X3-W3 -> 0.096527778 | Z3: =TEXT(U3, "YYYY-MM-DD aaa")&" ("&TEXT(W3, "hh:mm")&"~"&TEXT(X3, "hh:mm")&") : "&IF(MINUTE(Y3)=0, TEXT(Y3, "h시간"), TEXT(Y3, "h시간 m분")) -> 2025-01-30 목 (15:36~17:55) : 2시간 19분 | AB3: =_xlfn.XLOOKUP(I3, 기초데이터!$C$2:$C$305, 기초데이터!$U$2:$U$305) -> jsy@neurophet.com
A4: =SUBTOTAL(3,$I$2:I4)*1 -> 3 | B4: 25년 1월 | C4: 2025-01-29(08:30) ~ 2025-01-29(11:10) | D4: 1 | E4: 2.70시간 | F4: 0 | G4: AR3팀 | H4: Team Member | I4: 김기연 | J4: 24030401 | K4: 유연근무 | L4: 초과근무 | M4: 결재종결 | N4: 2025-01-31 | O4: 250128-30_AR2팀_김기연_유연근무신청서 (초과근무) | P4: 뉴로핏 주식회사-250131-AR2팀-0003 | T4: nnUnet 추가실험 output delivery & nnDet 실험 | U4: =DATEVALUE(LEFT(C4,10)) -> 45686 | V4: =WEEKNUM(U4,21) -> 5 | W4: =MID(C4,12,5) -> 08:30 | X4: =MID(C4,32,5) -> 11:10 | Y4: =X4-W4 -> 0.11111111 | Z4: =TEXT(U4, "YYYY-MM-DD aaa")&" ("&TEXT(W4, "hh:mm")&"~"&TEXT(X4, "hh:mm")&") : "&IF(MINUTE(Y4)=0, TEXT(Y4, "h시간"), TEXT(Y4, "h시간 m분")) -> 2025-01-29 수 (08:30~11:10) : 2시간 40분 | AB4: =_xlfn.XLOOKUP(I4, 기초데이터!$C$2:$C$305, 기초데이터!$U$2:$U$305) -> kgy@neurophet.com
A5: =SUBTOTAL(3,$I$2:I5)*1 -> 4 | B5: 25년 1월 | C5: 2025-01-29(15:53) ~ 2025-01-29(19:53) | D5: 1 | E5: 4.00시간 | F5: 0 | G5: AR1팀 | H5: Team Member | I5: 조상영 | J5: 23022701 | K5: 유연근무 | L5: 초과근무 | M5: 결재종결 | N5: 2025-02-03 | O5: 20250126, 250128, 250129, 250130 AR1팀 조상영 유연근무 신청서 (초과근무) | P5: 뉴로핏 주식회사-250203-AR1팀-0002 | T5: AQUA AD 3.0 통합 엔진 개발 | U5: =DATEVALUE(LEFT(C5,10)) -> 45686 | V5: =WEEKNUM(U5,21) -> 5 | W5: =MID(C5,12,5) -> 15:53 | X5: =MID(C5,32,5) -> 19:53 | Y5: =X5-W5 -> 0.16666667 | Z5: =TEXT(U5, "YYYY-MM-DD aaa")&" ("&TEXT(W5, "hh:mm")&"~"&TEXT(X5, "hh:mm")&") : "&IF(MINUTE(Y5)=0, TEXT(Y5, "h시간"), TEXT(Y5, "h시간 m분")) -> 2025-01-29 수 (15:53~19:53) : 4시간 | AB5: =_xlfn.XLOOKUP(I5, 기초데이터!$C$2:$C$305, 기초데이터!$U$2:$U$305) -> jsy@neurophet.com
A6: =SUBTOTAL(3,$I$2:I6)*1 -> 5 | B6: 25년 1월 | C6: 2025-01-29(21:30) ~ 2025-01-29(23:59) | D6: 1 | E6: 2.50시간 | F6: 0 | G6: AR3팀 | H6: Team Lead | I6: 양현식 | J6: 22030204 | K6: 유연근무 | L6: 초과근무 | M6: 결재종결 | N6: 2025-02-03 | O6: 20250127,28,29_AR3팀_양현식_유연근무신청서(초과근무) | P6: 뉴로핏 주식회사-250203-AR3팀-0004 | T6: coordconv 적용하기, rgs with seg 아이디어 적용하기 | U6: =DATEVALUE(LEFT(C6,10)) -> 45686 | V6: =WEEKNUM(U6,21) -> 5 | W6: =MID(C6,12,5) -> 21:30 | X6: =MID(C6,32,5) -> 23:59 | Y6: =X6-W6 -> 0.10347222 | Z6: =TEXT(U6, "YYYY-MM-DD aaa")&" ("&TEXT(W6, "hh:mm")&"~"&TEXT(X6, "hh:mm")&") : "&IF(MINUTE(Y6)=0, TEXT(Y6, "h시간"), TEXT(Y6, "h시간 m분")) -> 2025-01-29 수 (21:30~23:59) : 2시간 29분 | AB6: =_xlfn.XLOOKUP(I6, 기초데이터!$C$2:$C$305, 기초데이터!$U$2:$U$305) -> hsyang@neurophet.com
A7: =SUBTOTAL(3,$I$2:I7)*1 -> 6 | B7: 25년 1월 | C7: 2025-01-29(21:00) ~ 2025-01-29(23:59) | D7: 1 | E7: 3.00시간 | F7: 0 | G7: AR3팀 | H7: Team Member | I7: 김도연A | J7: 23091101 | K7: 유연근무 | L7: 초과근무 | M7: 결재종결 | N7: 2025-02-03 | O7: 20250203_AR3팀_김도연_유연근무신청서(초과근무) | P7: 뉴로핏 주식회사-250203-AR3팀-0003 | T7: - 조건 변경 후 결과 확인, loss 변경 후 실험 | U7: =DATEVALUE(LEFT(C7,10)) -> 45686 | V7: =WEEKNUM(U7,21) -> 5 | W7: =MID(C7,12,5) -> 21:00 | X7: =MID(C7,32,5) -> 23:59 | Y7: =X7-W7 -> 0.12430556 | Z7: =TEXT(U7, "YYYY-MM-DD aaa")&" ("&TEXT(W7, "hh:mm")&"~"&TEXT(X7, "hh:mm")&") : "&IF(MINUTE(Y7)=0, TEXT(Y7, "h시간"), TEXT(Y7, "h시간 m분")) -> 2025-01-29 수 (21:00~23:59) : 2시간 59분 | AB7: =_xlfn.XLOOKUP(I7, 기초데이터!$C$2:$C$305, 기초데이터!$U$2:$U$305) -> doyeon@neurophet.com
A8: =SUBTOTAL(3,$I$2:I8)*1 -> 7 | B8: 25년 1월 | C8: 2025-01-28(09:40) ~ 2025-01-28(12:50) | D8: 1 | E8: 3.20시간 | F8: 0 | G8: AR3팀 | H8: Team Member | I8: 김기연 | J8: 24030401 | K8: 유연근무 | L8: 초과근무 | M8: 결재종결 | N8: 2025-01-31 | O8: 250128-30_AR2팀_김기연_유연근무신청서 (초과근무) | P8: 뉴로핏 주식회사-250131-AR2팀-0003 | T8: nnDet 실험 & nnUnet 추가 실험 진행 | U8: =DATEVALUE(LEFT(C8,10)) -> 45685 | V8: =WEEKNUM(U8,21) -> 5 | W8: =MID(C8,12,5) -> 09:40 | X8: =MID(C8,32,5) -> 12:50 | Y8: =X8-W8 -> 0.13194444 | Z8: =TEXT(U8, "YYYY-MM-DD aaa")&" ("&TEXT(W8, "hh:mm")&"~"&TEXT(X8, "hh:mm")&") : "&IF(MINUTE(Y8)=0, TEXT(Y8, "h시간"), TEXT(Y8, "h시간 m분")) -> 2025-01-28 화 (09:40~12:50) : 3시간 10분 | AB8: =_xlfn.XLOOKUP(I8, 기초데이터!$C$2:$C$305, 기초데이터!$U$2:$U$305) -> kgy@neurophet.com
A9: =SUBTOTAL(3,$I$2:I9)*1 -> 8 | B9: 25년 1월 | C9: 2025-01-28(19:12) ~ 2025-01-28(22:06) | D9: 1 | E9: 2.90시간 | F9: 0 | G9: AR1팀 | H9: Team Member | I9: 조상영 | J9: 23022701 | K9: 유연근무 | L9: 초과근무 | M9: 결재종결 | N9: 2025-02-03 | O9: 20250126, 250128, 250129, 250130 AR1팀 조상영 유연근무 신청서 (초과근무) | P9: 뉴로핏 주식회사-250203-AR1팀-0002 | T9: AQUA AD 3.0 통합 엔진 개발 | U9: =DATEVALUE(LEFT(C9,10)) -> 45685 | V9: =WEEKNUM(U9,21) -> 5 | W9: =MID(C9,12,5) -> 19:12 | X9: =MID(C9,32,5) -> 22:06 | Y9: =X9-W9 -> 0.12083333 | Z9: =TEXT(U9, "YYYY-MM-DD aaa")&" ("&TEXT(W9, "hh:mm")&"~"&TEXT(X9, "hh:mm")&") : "&IF(MINUTE(Y9)=0, TEXT(Y9, "h시간"), TEXT(Y9, "h시간 m분")) -> 2025-01-28 화 (19:12~22:06) : 2시간 54분 | AB9: =_xlfn.XLOOKUP(I9, 기초데이터!$C$2:$C$305, 기초데이터!$U$2:$U$305) -> jsy@neurophet.com
A10: =SUBTOTAL(3,$I$2:I10)*1 -> 9 | B10: 25년 1월 | C10: 2025-01-28(10:50) ~ 2025-01-28(14:50) | D10: 1 | E10: 4.00시간 | F10: 0 | G10: AR3팀 | H10: Team Lead | I10: 양현식 | J10: 22030204 | K10: 유연근무 | L10: 초과근무 | M10: 결재종결 | N10: 2025-02-03 | O10: 20250127,28,29_AR3팀_양현식_유연근무신청서(초과근무) | P10: 뉴로핏 주식회사-250203-AR3팀-0004 | T10: center of mass를 loss에 적용하여보기 | U10: =DATEVALUE(LEFT(C10,10)) -> 45685 | V10: =WEEKNUM(U10,21) -> 5 | W10: =MID(C10,12,5) -> 10:50 | X10: =MID(C10,32,5) -> 14:50 | Y10: =X10-W10 -> 0.16666667 | Z10: =TEXT(U10, "YYYY-MM-DD aaa")&" ("&TEXT(W10, "hh:mm")&"~"&TEXT(X10, "hh:mm")&") : "&IF(MINUTE(Y10)=0, TEXT(Y10, "h시간"), TEXT(Y10, "h시간 m분")) -> 2025-01-28 화 (10:50~14:50) : 4시간 | AB10: =_xlfn.XLOOKUP(I10, 기초데이터!$C$2:$C$305, 기초데이터!$U$2:$U$305) -> hsyang@neurophet.com
A11: =SUBTOTAL(3,$I$2:I11)*1 -> 10 | B11: 25년 1월 | C11: 2025-01-28(11:40) ~ 2025-01-28(16:40) | D11: 1 | E11: 5.00시간 | F11: 0 | G11: AR3팀 | H11: Team Member | I11: 김도연A | J11: 23091101 | K11: 유연근무 | L11: 초과근무 | M11: 결재종결 | N11: 2025-02-03 | O11: 20250203_AR3팀_김도연_유연근무신청서(초과근무) | P11: 뉴로핏 주식회사-250203-AR3팀-0003 | T11: - 결과 추가 분석 | U11: =DATEVALUE(LEFT(C11,10)) -> 45685 | V11: =WEEKNUM(U11,21) -> 5 | W11: =MID(C11,12,5) -> 11:40 | X11: =MID(C11,32,5) -> 16:40 | Y11: =X11-W11 -> 0.20833333 | Z11: =TEXT(U11, "YYYY-MM-DD aaa")&" ("&TEXT(W11, "hh:mm")&"~"&TEXT(X11, "hh:mm")&") : "&IF(MINUTE(Y11)=0, TEXT(Y11, "h시간"), TEXT(Y11, "h시간 m분")) -> 2025-01-28 화 (11:40~16:40) : 5시간 | AB11: =_xlfn.XLOOKUP(I11, 기초데이터!$C$2:$C$305, 기초데이터!$U$2:$U$305) -> doyeon@neurophet.com
A12: =SUBTOTAL(3,$I$2:I12)*1 -> 11 | B12: 25년 1월 | C12: 2025-01-27(10:06) ~ 2025-01-27(15:47) | D12: 1 | E12: 5.70시간 | F12: 0 | G12: AR1팀 | H12: Team Member | I12: 김다현 | J12: 24060302 | K12: 유연근무 | L12: 초과근무 | M12: 결재종결 | N12: 2025-02-04 | O12: 250125,250127_AR1팀(김다현)_유연근무(초과근무) | P12: 뉴로핏 주식회사-250203-AR1팀-0003 | T12: SEG-03 fine-tuning_v3 실험 결과 확인 및 정리, SWI, GRE 데이터 확인 | U12: =DATEVALUE(LEFT(C12,10)) -> 45684 | V12: =WEEKNUM(U12,21) -> 5 | W12: =MID(C12,12,5) -> 10:06 | X12: =MID(C12,32,5) -> 15:47 | Y12: =X12-W12 -> 0.23680556 | Z12: =TEXT(U12, "YYYY-MM-DD aaa")&" ("&TEXT(W12, "hh:mm")&"~"&TEXT(X12, "hh:mm")&") : "&IF(MINUTE(Y12)=0, TEXT(Y12, "h시간"), TEXT(Y12, "h시간 m분")) -> 2025-01-27 월 (10:06~15:47) : 5시간 41분 | AB12: =_xlfn.XLOOKUP(I12, 기초데이터!$C$2:$C$305, 기초데이터!$U$2:$U$305) -> dahyun@neurophet.com
A13: =SUBTOTAL(3,$I$2:I13)*1 -> 12 | B13: 25년 1월 | C13: 2025-01-27(14:00) ~ 2025-01-27(16:20) | D13: 1 | E13: 2.30시간 | F13: 0 | G13: AR3팀 | H13: Team Lead | I13: 양현식 | J13: 22030204 | K13: 유연근무 | L13: 초과근무 | M13: 결재종결 | N13: 2025-02-03 | O13: 20250127,28,29_AR3팀_양현식_유연근무신청서(초과근무) | P13: 뉴로핏 주식회사-250203-AR3팀-0004 | T13: qc 데이터셋 적용 및 crop4x 실험 | U13: =DATEVALUE(LEFT(C13,10)) -> 45684 | V13: =WEEKNUM(U13,21) -> 5 | W13: =MID(C13,12,5) -> 14:00 | X13: =MID(C13,32,5) -> 16:20 | Y13: =X13-W13 -> 0.097222222 | Z13: =TEXT(U13, "YYYY-MM-DD aaa")&" ("&TEXT(W13, "hh:mm")&"~"&TEXT(X13, "hh:mm")&") : "&IF(MINUTE(Y13)=0, TEXT(Y13, "h시간"), TEXT(Y13, "h시간 m분")) -> 2025-01-27 월 (14:00~16:20) : 2시간 20분 | AB13: =_xlfn.XLOOKUP(I13, 기초데이터!$C$2:$C$305, 기초데이터!$U$2:$U$305) -> hsyang@neurophet.com
... A51: =SUBTOTAL(3,$I$2:I51)*1 -> 50 | B51: 25년 1월 | C51: 2025-01-07(16:00) ~ 2025-01-07(20:00) | D51: 1 | E51: 4.00시간 | F51: 0 | G51: Platform팀 | H51: Team Member | I51: 성형모 | J51: 22022101 | K51: 유연근무 | L51: 초과근무 | M51: 결재종결 | N51: 2025-01-21 | O51: 20250120_유연근무신청서_성형모 | P51: 뉴로핏 주식회사-250120-Platform팀-0001 | T51: CTP MV 버그 처리 및 PET MV 버그 처리 건이 ASAP으로 진행되어야 하는 관계로 탄력 근무를 신청 | U51: =DATEVALUE(LEFT(C51,10)) -> 45664 | V51: =WEEKNUM(U51,21) -> 2 | W51: =MID(C51,12,5) -> 16:00 | X51: =MID(C51,32,5) -> 20:00 | Y51: =X51-W51 -> 0.16666667 | Z51: =TEXT(U51, "YYYY-MM-DD aaa")&" ("&TEXT(W51, "hh:mm")&"~"&TEXT(X51, "hh:mm")&") : "&IF(MINUTE(Y51)=0, TEXT(Y51, "h시간"), TEXT(Y51, "h시간 m분")) -> 2025-01-07 화 (16:00~20:00) : 4시간 | AB51: =_xlfn.XLOOKUP(I51, 기초데이터!$C$2:$C$305, 기초데이터!$U$2:$U$305) -> hmseong@neurophet.com
A52: =SUBTOTAL(3,$I$2:I52)*1 -> 51 | B52: 25년 1월 | C52: 2025-01-06(17:30) ~ 2025-01-06(20:00) | D52: 1 | E52: 2.50시간 | F52: 0 | G52: 뇌자극팀 | H52: Team Member | I52: 홍락균 | J52: 24022001 | K52: 유연근무 | L52: 초과근무 | M52: 결재종결 | N52: 2025-01-07 | O52: 250106_뇌자극팀_홍락균_초과근무신청서 | P52: 뉴로핏 주식회사-250107-뇌자극팀-0001 | U52: =DATEVALUE(LEFT(C52,10)) -> 45663 | V52: =WEEKNUM(U52,21) -> 2 | W52: =MID(C52,12,5) -> 17:30 | X52: =MID(C52,32,5) -> 20:00 | Y52: =X52-W52 -> 0.10416667 | Z52: =TEXT(U52, "YYYY-MM-DD aaa")&" ("&TEXT(W52, "hh:mm")&"~"&TEXT(X52, "hh:mm")&") : "&IF(MINUTE(Y52)=0, TEXT(Y52, "h시간"), TEXT(Y52, "h시간 m분")) -> 2025-01-06 월 (17:30~20:00) : 2시간 30분 | AB52: =_xlfn.XLOOKUP(I52, 기초데이터!$C$2:$C$305, 기초데이터!$U$2:$U$305) -> rkhong@neurophet.com
A53: =SUBTOTAL(3,$I$2:I53)*1 -> 52 | B53: 25년 1월 | C53: 2025-01-06(18:11) ~ 2025-01-06(20:19) | D53: 1 | E53: 2.10시간 | F53: 0 | G53: 임상팀 | H53: Team Member | I53: 장한나 | J53: 21122001 | K53: 유연근무 | L53: 초과근무 | M53: 결재종결 | N53: 2025-01-10 | O53: 20250106_임상팀 장한나_유연근무 신청의 건 | P53: 뉴로핏 주식회사-250110-임상팀-0004 | T53: tDCS 정기미팅 및 S02 CRF 작성 | U53: =DATEVALUE(LEFT(C53,10)) -> 45663 | V53: =WEEKNUM(U53,21) -> 2 | W53: =MID(C53,12,5) -> 18:11 | X53: =MID(C53,32,5) -> 20:19 | Y53: =X53-W53 -> 0.088888889 | Z53: =TEXT(U53, "YYYY-MM-DD aaa")&" ("&TEXT(W53, "hh:mm")&"~"&TEXT(X53, "hh:mm")&") : "&IF(MINUTE(Y53)=0, TEXT(Y53, "h시간"), TEXT(Y53, "h시간 m분")) -> 2025-01-06 월 (18:11~20:19) : 2시간 8분 | AB53: =_xlfn.XLOOKUP(I53, 기초데이터!$C$2:$C$305, 기초데이터!$U$2:$U$305) -> hnjang@neurophet.com
A54: =SUBTOTAL(3,$I$2:I54)*1 -> 53 | B54: 25년 1월 | C54: 2025-01-06(17:20) ~ 2025-01-06(20:19) | D54: 1 | E54: 3.00시간 | F54: 0 | G54: 임상팀 | H54: Team Lead | I54: 송단비 | J54: 20070103 | K54: 유연근무 | L54: 초과근무 | M54: 결재종결 | N54: 2025-01-13 | O54: 250106,11_송단비_유연근무 신청의 건 (초과근로) | P54: 뉴로핏 주식회사-250113-임상팀-0002 | T54: C03 / C12 / tDCS 연구자미팅 | U54: =DATEVALUE(LEFT(C54,10)) -> 45663 | V54: =WEEKNUM(U54,21) -> 2 | W54: =MID(C54,12,5) -> 17:20 | X54: =MID(C54,32,5) -> 20:19 | Y54: =X54-W54 -> 0.12430556 | Z54: =TEXT(U54, "YYYY-MM-DD aaa")&" ("&TEXT(W54, "hh:mm")&"~"&TEXT(X54, "hh:mm")&") : "&IF(MINUTE(Y54)=0, TEXT(Y54, "h시간"), TEXT(Y54, "h시간 m분")) -> 2025-01-06 월 (17:20~20:19) : 2시간 59분 | AB54: =_xlfn.XLOOKUP(I54, 기초데이터!$C$2:$C$305, 기초데이터!$U$2:$U$305) -> dbsong@neurophet.com
A55: =SUBTOTAL(3,$I$2:I55)*1 -> 54 | B55: 25년 1월 | C55: 2025-01-06(18:15) ~ 2025-01-06(20:19) | D55: 1 | E55: 2.10시간 | F55: 0 | G55: 임상팀 | H55: Team Member | I55: 이승은 | J55: 21031501 | K55: 유연근무 | L55: 초과근무 | M55: 결재종결 | N55: 2025-01-13 | O55: 250106_임상팀 이승은_유연근무 신청의 건 | P55: 뉴로핏 주식회사-250113-임상팀-0006 | T55: tDCS 연구자 정기미팅, 식약처 상담 내용 정리 | U55: =DATEVALUE(LEFT(C55,10)) -> 45663 | V55: =WEEKNUM(U55,21) -> 2 | W55: =MID(C55,12,5) -> 18:15 | X55: =MID(C55,32,5) -> 20:19 | Y55: =X55-W55 -> 0.086111111 | Z55: =TEXT(U55, "YYYY-MM-DD aaa")&" ("&TEXT(W55, "hh:mm")&"~"&TEXT(X55, "hh:mm")&") : "&IF(MINUTE(Y55)=0, TEXT(Y55, "h시간"), TEXT(Y55, "h시간 m분")) -> 2025-01-06 월 (18:15~20:19) : 2시간 4분 | AB55: =_xlfn.XLOOKUP(I55, 기초데이터!$C$2:$C$305, 기초데이터!$U$2:$U$305) -> selee@neurophet.com
A56: =SUBTOTAL(3,$I$2:I56)*1 -> 55 | B56: 25년 1월 | C56: 2025-01-06(17:06) ~ 2025-01-06(19:11) | D56: 1 | E56: 2.10시간 | F56: 0 | G56: AR3팀 | H56: Team Member | I56: 김도연A | J56: 23091101 | K56: 유연근무 | L56: 초과근무 | M56: 결재종결 | N56: 2025-01-14 | O56: 250114_AR2팀_김도연_초과근무 신청 | P56: 뉴로핏 주식회사-250114-AR2팀-0001 | T56: box regression 조건 변경 후 실험 | U56: =DATEVALUE(LEFT(C56,10)) -> 45663 | V56: =WEEKNUM(U56,21) -> 2 | W56: =MID(C56,12,5) -> 17:06 | X56: =MID(C56,32,5) -> 19:11 | Y56: =X56-W56 -> 0.086805556 | Z56: =TEXT(U56, "YYYY-MM-DD aaa")&" ("&TEXT(W56, "hh:mm")&"~"&TEXT(X56, "hh:mm")&") : "&IF(MINUTE(Y56)=0, TEXT(Y56, "h시간"), TEXT(Y56, "h시간 m분")) -> 2025-01-06 월 (17:06~19:11) : 2시간 5분 | AB56: =_xlfn.XLOOKUP(I56, 기초데이터!$C$2:$C$305, 기초데이터!$U$2:$U$305) -> doyeon@neurophet.com
A57: =SUBTOTAL(3,$I$2:I57)*1 -> 56 | B57: 25년 1월 | C57: 2025-01-03(18:39) ~ 2025-01-03(20:39) | D57: 1 | E57: 2.00시간 | F57: 0 | G57: PET팀 | H57: Team Member | I57: 김상덕 | J57: 22110701 | K57: 유연근무 | L57: 초과근무 | M57: 결재종결 | N57: 2025-01-06 | O57: 20250103_김상덕_초과근무 | P57: 뉴로핏 주식회사-250103-PET팀-0002 | T57: ScalePet 2.1 MV2차 를 위한 insaller build 및 테스트 | U57: =DATEVALUE(LEFT(C57,10)) -> 45660 | V57: =WEEKNUM(U57,21) -> 1 | W57: =MID(C57,12,5) -> 18:39 | X57: =MID(C57,32,5) -> 20:39 | Y57: =X57-W57 -> 0.083333333 | Z57: =TEXT(U57, "YYYY-MM-DD aaa")&" ("&TEXT(W57, "hh:mm")&"~"&TEXT(X57, "hh:mm")&") : "&IF(MINUTE(Y57)=0, TEXT(Y57, "h시간"), TEXT(Y57, "h시간 m분")) -> 2025-01-03 금 (18:39~20:39) : 2시간 | AB57: =_xlfn.XLOOKUP(I57, 기초데이터!$C$2:$C$305, 기초데이터!$U$2:$U$305) -> sdkim@neurophet.com
A58: =SUBTOTAL(3,$I$2:I58)*1 -> 57 | B58: 25년 1월 | C58: 2025-01-03(16:00) ~ 2025-01-03(18:30) | D58: 1 | E58: 2.50시간 | F58: 0 | G58: SV팀 | H58: Team Lead | I58: 김가희 | J58: 22011702 | K58: 유연근무 | L58: 초과근무 | M58: 결재종결 | N58: 2025-01-06 | O58: 250103_SV팀(김가희)_유연근무 신청 | P58: 뉴로핏 주식회사-250103-SV팀-0002 | T58: SCALE CTP 1.0 MV 2차 검증 | U58: =DATEVALUE(LEFT(C58,10)) -> 45660 | V58: =WEEKNUM(U58,21) -> 1 | W58: =MID(C58,12,5) -> 16:00 | X58: =MID(C58,32,5) -> 18:30 | Y58: =X58-W58 -> 0.10416667 | Z58: =TEXT(U58, "YYYY-MM-DD aaa")&" ("&TEXT(W58, "hh:mm")&"~"&TEXT(X58, "hh:mm")&") : "&IF(MINUTE(Y58)=0, TEXT(Y58, "h시간"), TEXT(Y58, "h시간 m분")) -> 2025-01-03 금 (16:00~18:30) : 2시간 30분 | AB58: =_xlfn.XLOOKUP(I58, 기초데이터!$C$2:$C$305, 기초데이터!$U$2:$U$305) -> kahee@neurophet.com
A59: =SUBTOTAL(3,$I$2:I59)*1 -> 58 | B59: 25년 1월 | C59: 2025-01-02(16:30) ~ 2025-01-02(19:30) | D59: 1 | E59: 3.00시간 | F59: 0 | G59: QA팀 | H59: Team Lead | I59: 조용우 | J59: 22041101 | K59: 유연근무 | L59: 초과근무 | M59: 결재종결 | N59: 2025-01-02 | O59: [20250102]QA팀 조용우 초과 근무 신청 | P59: 뉴로핏 주식회사-250102-QA-0001 | T59: MDSAP 후속 조치 및 디지털의료제품법 적용 준 | U59: =DATEVALUE(LEFT(C59,10)) -> 45659 | V59: =WEEKNUM(U59,21) -> 1 | W59: =MID(C59,12,5) -> 16:30 | X59: =MID(C59,32,5) -> 19:30 | Y59: =X59-W59 -> 0.125 | Z59: =TEXT(U59, "YYYY-MM-DD aaa")&" ("&TEXT(W59, "hh:mm")&"~"&TEXT(X59, "hh:mm")&") : "&IF(MINUTE(Y59)=0, TEXT(Y59, "h시간"), TEXT(Y59, "h시간 m분")) -> 2025-01-02 목 (16:30~19:30) : 3시간 | AB59: =_xlfn.XLOOKUP(I59, 기초데이터!$C$2:$C$305, 기초데이터!$U$2:$U$305) -> ywcho@neurophet.com
A60: =SUBTOTAL(3,$I$2:I60)*1 -> 59 | B60: 25년 1월 | C60: 2025-01-02(17:15) ~ 2025-01-02(20:10) | D60: 1 | E60: 2.90시간 | F60: 0 | G60: Vascular팀 | H60: Team Member | I60: 조은혜 | J60: 22040101 | K60: 유연근무 | L60: 초과근무 | M60: 결재종결 | N60: 2025-01-06 | O60: 250103_조은혜_유연근무신청서 | P60: 뉴로핏 주식회사-250103-Vascular팀-0002 | T60: SCALE CTP vulnerability issue fix | U60: =DATEVALUE(LEFT(C60,10)) -> 45659 | V60: =WEEKNUM(U60,21) -> 1 | W60: =MID(C60,12,5) -> 17:15 | X60: =MID(C60,32,5) -> 20:10 | Y60: =X60-W60 -> 0.12152778 | Z60: =TEXT(U60, "YYYY-MM-DD aaa")&" ("&TEXT(W60, "hh:mm")&"~"&TEXT(X60, "hh:mm")&") : "&IF(MINUTE(Y60)=0, TEXT(Y60, "h시간"), TEXT(Y60, "h시간 m분")) -> 2025-01-02 목 (17:15~20:10) : 2시간 55분 | AB60: =_xlfn.XLOOKUP(I60, 기초데이터!$C$2:$C$305, 기초데이터!$U$2:$U$305) -> eunhyecho@neurophet.com
A61: =SUBTOTAL(3,$I$2:I61)*1 -> 60 | B61: 25년 1월 | C61: 2025-01-02(17:34) ~ 2025-01-02(19:08) | D61: 1 | E61: 1.60시간 | F61: 0 | G61: 마케팅팀 | H61: Team Member | I61: 서충원 | J61: 24011503 | K61: 유연근무 | L61: 초과근무 | M61: 결재종결 | N61: 2025-01-03 | O61: 250102_mkt(서충원)_초과근무내역 | P61: 뉴로핏 주식회사-250103-마케팅-0001 | T61: MS 부스 디자인 작업 | U61: =DATEVALUE(LEFT(C61,10)) -> 45659 | V61: =WEEKNUM(U61,21) -> 1 | W61: =MID(C61,12,5) -> 17:34 | X61: =MID(C61,32,5) -> 19:08 | Y61: =X61-W61 -> 0.065277778 | Z61: =TEXT(U61, "YYYY-MM-DD aaa")&" ("&TEXT(W61, "hh:mm")&"~"&TEXT(X61, "hh:mm")&") : "&IF(MINUTE(Y61)=0, TEXT(Y61, "h시간"), TEXT(Y61, "h시간 m분")) -> 2025-01-02 목 (17:34~19:08) : 1시간 34분 | AB61: =_xlfn.XLOOKUP(I61, 기초데이터!$C$2:$C$305, 기초데이터!$U$2:$U$305) -> cwseo@neurophet.com
A62: =SUBTOTAL(3,$I$2:I62)*1 -> 61 | B62: 25년 1월 | C62: 2025-01-02(19:00) ~ 2025-01-02(22:15) | D62: 1 | E62: 3.30시간 | F62: 0 | G62: NR1팀 | H62: Team Member | I62: 박지은 | J62: 24031101 | K62: 유연근무 | L62: 초과근무 | M62: 결재종결 | N62: 2025-01-08 | O62: 250102_NR1팀_박지은_유연근무신청(초과근무) | P62: 뉴로핏 주식회사-250108-NR1팀-0001 | T62: 질병청 DTI preprocessing | U62: =DATEVALUE(LEFT(C62,10)) -> 45659 | V62: =WEEKNUM(U62,21) -> 1 | W62: =MID(C62,12,5) -> 19:00 | X62: =MID(C62,32,5) -> 22:15 | Y62: =X62-W62 -> 0.13541667 | Z62: =TEXT(U62, "YYYY-MM-DD aaa")&" ("&TEXT(W62, "hh:mm")&"~"&TEXT(X62, "hh:mm")&") : "&IF(MINUTE(Y62)=0, TEXT(Y62, "h시간"), TEXT(Y62, "h시간 m분")) -> 2025-01-02 목 (19:00~22:15) : 3시간 15분 | AB62: =_xlfn.XLOOKUP(I62, 기초데이터!$C$2:$C$305, 기초데이터!$U$2:$U$305) -> jieunpark@neurophet.com
A63: =SUBTOTAL(3,$I$2:I63)*1 -> 62 | B63: 25년 2월 | C63: 2025-01-13(17:32) ~ 2025-01-13(20:28) | D63: 1 | E63: 2.90시간 | F63: 0 | G63: IR팀 | H63: Team Member | I63: 유용성 | J63: 24101401 | K63: 유연근무 | L63: 초과근무 | M63: 결재종결 | N63: 2025-02-14 | O63: 202501_유용성(IR팀)_초과 근무 신처 | P63: 뉴로핏 주식회사-250214-IR팀-0003 | T63: 우선주 전환을 위한 예탁원 사선짐사 자료 작업 | U63: =DATEVALUE(LEFT(C63,10)) -> 45670 | V63: =WEEKNUM(U63,21) -> 3 | W63: =MID(C63,12,5) -> 17:32 | X63: =MID(C63,32,5) -> 20:28 | Y63: =X63-W63 -> 0.12222222 | Z63: =TEXT(U63, "YYYY-MM-DD aaa")&" ("&TEXT(W63, "hh:mm")&"~"&TEXT(X63, "hh:mm")&") : "&IF(MINUTE(Y63)=0, TEXT(Y63, "h시간"), TEXT(Y63, "h시간 m분")) -> 2025-01-13 월 (17:32~20:28) : 2시간 56분 | AB63: =_xlfn.XLOOKUP(I63, 기초데이터!$C$2:$C$305, 기초데이터!$U$2:$U$305) -> noah@neurophet.com
A64: =SUBTOTAL(3,$I$2:I64)*1 -> 63 | B64: 25년 2월 | C64: 2025-01-15(17:34) ~ 2025-01-15(19:39) | D64: 1 | E64: 2.10시간 | F64: 0 | G64: IR팀 | H64: Team Member | I64: 유용성 | J64: 24101401 | K64: 유연근무 | L64: 초과근무 | M64: 결재종결 | N64: 2025-02-14 | O64: 202501_유용성(IR팀)_초과 근무 신처 | P64: 뉴로핏 주식회사-250214-IR팀-0003 | T64: 우선주 전환을 위한 예탁원 사전심사 자료 작업 | U64: =DATEVALUE(LEFT(C64,10)) -> 45672 | V64: =WEEKNUM(U64,21) -> 3 | W64: =MID(C64,12,5) -> 17:34 | X64: =MID(C64,32,5) -> 19:39 | Y64: =X64-W64 -> 0.086805556 | Z64: =TEXT(U64, "YYYY-MM-DD aaa")&" ("&TEXT(W64, "hh:mm")&"~"&TEXT(X64, "hh:mm")&") : "&IF(MINUTE(Y64)=0, TEXT(Y64, "h시간"), TEXT(Y64, "h시간 m분")) -> 2025-01-15 수 (17:34~19:39) : 2시간 5분 | AB64: =_xlfn.XLOOKUP(I64, 기초데이터!$C$2:$C$305, 기초데이터!$U$2:$U$305) -> noah@neurophet.com
... A143: =SUBTOTAL(3,$I$2:I143)*1 -> 142 | B143: 25년 2월 | C143: 2025-02-17(17:43) ~ 2025-02-17(21:43) | D143: 1 | E143: 4.00시간 | F143: 0 | G143: AQUA팀 | H143: Team Member | I143: 이승룡 | J143: 22121901 | K143: 유연근무 | L143: 초과근무 | M143: 결재종결 | N143: 2025-02-21 | O143: 250221_AQUA팀_이승룡 유연근무 신청 | P143: 뉴로핏 주식회사-250221-AQUA팀-0002 | T143: Normative Engine pipeline 인터페이스 구현 및 AQUA 환경 실행 | U143: =DATEVALUE(LEFT(C143,10)) -> 45705 | V143: =WEEKNUM(U143,21) -> 8 | W143: =MID(C143,12,5) -> 17:43 | X143: =MID(C143,32,5) -> 21:43 | Y143: =X143-W143 -> 0.16666667 | Z143: =TEXT(U143, "YYYY-MM-DD aaa")&" ("&TEXT(W143, "hh:mm")&"~"&TEXT(X143, "hh:mm")&") : "&IF(MINUTE(Y143)=0, TEXT(Y143, "h시간"), TEXT(Y143, "h시간 m분")) -> 2025-02-17 월 (17:43~21:43) : 4시간 | AB143: =_xlfn.XLOOKUP(I143, 기초데이터!$C$2:$C$305, 기초데이터!$U$2:$U$305) -> lsr@neurophet.com
A144: =SUBTOTAL(3,$I$2:I144)*1 -> 143 | B144: 25년 2월 | C144: 2025-02-18(17:00) ~ 2025-02-18(21:00) | D144: 1 | E144: 4.00시간 | F144: 0 | G144: AQUA팀 | H144: Team Member | I144: 강신일 | K144: 유연근무 | L144: 초과근무 | M144: 결재종결 | N144: 2025-02-19 | O144: 250218_AQUA팀_강신일 유연근무신청 | P144: 뉴로핏 주식회사-250219-AQUA팀-0001 | T144: NeuroMap Label Data Export 데이터 모델 정의 및 기능 구현 | U144: =DATEVALUE(LEFT(C144,10)) -> 45706 | V144: =WEEKNUM(U144,21) -> 8 | W144: =MID(C144,12,5) -> 17:00 | X144: =MID(C144,32,5) -> 21:00 | Y144: =X144-W144 -> 0.16666667 | Z144: =TEXT(U144, "YYYY-MM-DD aaa")&" ("&TEXT(W144, "hh:mm")&"~"&TEXT(X144, "hh:mm")&") : "&IF(MINUTE(Y144)=0, TEXT(Y144, "h시간"), TEXT(Y144, "h시간 m분")) -> 2025-02-18 화 (17:00~21:00) : 4시간 | AB144: =_xlfn.XLOOKUP(I144, 기초데이터!$C$2:$C$305, 기초데이터!$U$2:$U$305) -> sikang@neurophet.com
A145: =SUBTOTAL(3,$I$2:I145)*1 -> 144 | B145: 25년 2월 | C145: 2025-02-18(17:25) ~ 2025-02-18(21:25) | D145: 1 | E145: 4.00시간 | F145: 0 | G145: AQUA팀 | H145: Team Member | I145: 이승룡 | J145: 22121901 | K145: 유연근무 | L145: 초과근무 | M145: 결재종결 | N145: 2025-02-21 | O145: 250221_AQUA팀_이승룡 유연근무 신청 | P145: 뉴로핏 주식회사-250221-AQUA팀-0002 | T145: Anomaly Engine pipeline 인터페이스 구현 및 AQUA 환경 실행 | U145: =DATEVALUE(LEFT(C145,10)) -> 45706 | V145: =WEEKNUM(U145,21) -> 8 | W145: =MID(C145,12,5) -> 17:25 | X145: =MID(C145,32,5) -> 21:25 | Y145: =X145-W145 -> 0.16666667 | Z145: =TEXT(U145, "YYYY-MM-DD aaa")&" ("&TEXT(W145, "hh:mm")&"~"&TEXT(X145, "hh:mm")&") : "&IF(MINUTE(Y145)=0, TEXT(Y145, "h시간"), TEXT(Y145, "h시간 m분")) -> 2025-02-18 화 (17:25~21:25) : 4시간 | AB145: =_xlfn.XLOOKUP(I145, 기초데이터!$C$2:$C$305, 기초데이터!$U$2:$U$305) -> lsr@neurophet.com
A146: =SUBTOTAL(3,$I$2:I146)*1 -> 145 | B146: 25년 2월 | C146: 2025-02-18(17:27) ~ 2025-02-18(20:59) | D146: 1 | E146: 3.50시간 | F146: 0 | G146: IR팀 | H146: Team Member | I146: 유용성 | J146: 24101401 | K146: 유연근무 | L146: 초과근무 | M146: 결재종결 | N146: 2025-03-11 | O146: 202502_유용성(IR팀)_초과 근무 신청 | P146: 뉴로핏 주식회사-250311-IR팀-0001 | T146: 예심신청서, 투자기관 요청 대응 등 | U146: =DATEVALUE(LEFT(C146,10)) -> 45706 | V146: =WEEKNUM(U146,21) -> 8 | W146: =MID(C146,12,5) -> 17:27 | X146: =MID(C146,32,5) -> 20:59 | Y146: =X146-W146 -> 0.14722222 | Z146: =TEXT(U146, "YYYY-MM-DD aaa")&" ("&TEXT(W146, "hh:mm")&"~"&TEXT(X146, "hh:mm")&") : "&IF(MINUTE(Y146)=0, TEXT(Y146, "h시간"), TEXT(Y146, "h시간 m분")) -> 2025-02-18 화 (17:27~20:59) : 3시간 32분 | AB146: =_xlfn.XLOOKUP(I146, 기초데이터!$C$2:$C$305, 기초데이터!$U$2:$U$305) -> noah@neurophet.com
A147: =SUBTOTAL(3,$I$2:I147)*1 -> 146 | B147: 25년 2월 | C147: 2025-02-18(17:30) ~ 2025-02-18(19:30) | D147: 1 | E147: 2.00시간 | F147: 0 | G147: AD팀 | H147: Team Lead | I147: 서강희 | J147: 22060201 | K147: 유연근무 | L147: 초과근무 | M147: 결재종결 | N147: 2025-02-19 | O147: 250218 서강희 유연근무 신청 | P147: 뉴로핏 주식회사-250218-AD팀-0001 | T147: AQUA AD 3.0 NeuroEngine 적용, PET 분석 pipeline 구현, ARIA-E 분석 리뷰 | U147: =DATEVALUE(LEFT(C147,10)) -> 45706 | V147: =WEEKNUM(U147,21) -> 8 | W147: =MID(C147,12,5) -> 17:30 | X147: =MID(C147,32,5) -> 19:30 | Y147: =X147-W147 -> 0.083333333 | Z147: =TEXT(U147, "YYYY-MM-DD aaa")&" ("&TEXT(W147, "hh:mm")&"~"&TEXT(X147, "hh:mm")&") : "&IF(MINUTE(Y147)=0, TEXT(Y147, "h시간"), TEXT(Y147, "h시간 m분")) -> 2025-02-18 화 (17:30~19:30) : 2시간 | AB147: =_xlfn.XLOOKUP(I147, 기초데이터!$C$2:$C$305, 기초데이터!$U$2:$U$305) -> kelly.seo@neurophet.com
A148: =SUBTOTAL(3,$I$2:I148)*1 -> 147 | B148: 25년 2월 | C148: 2025-02-18(19:25) ~ 2025-02-18(21:40) | D148: 1 | E148: 2.30시간 | F148: 0 | G148: AQUA팀 | H148: Team Lead | I148: 전만재 | J148: 22021404 | K148: 유연근무 | L148: 초과근무 | M148: 결재종결 | N148: 2025-02-19 | O148: 250218_AQUA팀_전만재_유연근무 신청 | P148: 뉴로핏 주식회사-250218-AQUA팀-0002 | T148: AQUA 3.2 M1 DHF 작성 기한 준수 | U148: =DATEVALUE(LEFT(C148,10)) -> 45706 | V148: =WEEKNUM(U148,21) -> 8 | W148: =MID(C148,12,5) -> 19:25 | X148: =MID(C148,32,5) -> 21:40 | Y148: =X148-W148 -> 0.09375 | Z148: =TEXT(U148, "YYYY-MM-DD aaa")&" ("&TEXT(W148, "hh:mm")&"~"&TEXT(X148, "hh:mm")&") : "&IF(MINUTE(Y148)=0, TEXT(Y148, "h시간"), TEXT(Y148, "h시간 m분")) -> 2025-02-18 화 (19:25~21:40) : 2시간 15분 | AB148: =_xlfn.XLOOKUP(I148, 기초데이터!$C$2:$C$305, 기초데이터!$U$2:$U$305) -> manjae.jeon@neurophet.com
A149: =SUBTOTAL(3,$I$2:I149)*1 -> 148 | B149: 25년 2월 | C149: 2025-02-19(16:34) ~ 2025-02-19(19:10) | D149: 1 | E149: 2.60시간 | F149: 0 | G149: AR1팀 | H149: Team Member | I149: 김다현 | J149: 24060302 | K149: 유연근무 | L149: 초과근무 | M149: 결재종결 | N149: 2025-02-20 | O149: 250219_AR1팀(김다현)_유연근무(초과근무) | P149: 뉴로핏 주식회사-250220-AR1팀-0003 | T149: ARIA-H 데이터 전처리 후 MSFF-nnUNet baseline 모델 훈련 시작 | U149: =DATEVALUE(LEFT(C149,10)) -> 45707 | V149: =WEEKNUM(U149,21) -> 8 | W149: =MID(C149,12,5) -> 16:34 | X149: =MID(C149,32,5) -> 19:10 | Y149: =X149-W149 -> 0.10833333 | Z149: =TEXT(U149, "YYYY-MM-DD aaa")&" ("&TEXT(W149, "hh:mm")&"~"&TEXT(X149, "hh:mm")&") : "&IF(MINUTE(Y149)=0, TEXT(Y149, "h시간"), TEXT(Y149, "h시간 m분")) -> 2025-02-19 수 (16:34~19:10) : 2시간 36분 | AB149: =_xlfn.XLOOKUP(I149, 기초데이터!$C$2:$C$305, 기초데이터!$U$2:$U$305) -> dahyun@neurophet.com
A150: =SUBTOTAL(3,$I$2:I150)*1 -> 149 | B150: 25년 2월 | C150: 2025-02-19(16:40) ~ 2025-02-19(20:40) | D150: 1 | E150: 4.00시간 | F150: 0 | G150: Platform팀 | H150: Team Member | I150: 성형모 | J150: 22022101 | K150: 유연근무 | L150: 초과근무 | M150: 결재종결 | N150: 2025-03-09 | O150: 20250307_유연근무신청서_성형모 | P150: 뉴로핏 주식회사-250307-Platform팀-0001 | T150: Inhouse 엔진 클러스터 서버 구성 및 NEO2.0 엔진 브로커 인터페이스 구현을 위한 탄력 근무 | U150: =DATEVALUE(LEFT(C150,10)) -> 45707 | V150: =WEEKNUM(U150,21) -> 8 | W150: =MID(C150,12,5) -> 16:40 | X150: =MID(C150,32,5) -> 20:40 | Y150: =X150-W150 -> 0.16666667 | Z150: =TEXT(U150, "YYYY-MM-DD aaa")&" ("&TEXT(W150, "hh:mm")&"~"&TEXT(X150, "hh:mm")&") : "&IF(MINUTE(Y150)=0, TEXT(Y150, "h시간"), TEXT(Y150, "h시간 m분")) -> 2025-02-19 수 (16:40~20:40) : 4시간 | AB150: =_xlfn.XLOOKUP(I150, 기초데이터!$C$2:$C$305, 기초데이터!$U$2:$U$305) -> hmseong@neurophet.com
A151: =SUBTOTAL(3,$I$2:I151)*1 -> 150 | B151: 25년 2월 | C151: 2025-02-19(17:00) ~ 2025-02-19(19:10) | D151: 1 | E151: 2.20시간 | F151: 0 | G151: PR팀 | H151: Team Member | I151: 윤재정 | J151: 22031501 | K151: 유연근무 | L151: 초과근무 | M151: 결재종결 | N151: 2025-03-05 | O151: 250219_PR팀(윤재정)_초과근무신청 | P151: 뉴로핏 주식회사-250305-PR팀-0002 | T151: 상장신청준비 보조 | U151: =DATEVALUE(LEFT(C151,10)) -> 45707 | V151: =WEEKNUM(U151,21) -> 8 | W151: =MID(C151,12,5) -> 17:00 | X151: =MID(C151,32,5) -> 19:10 | Y151: =X151-W151 -> 0.090277778 | Z151: =TEXT(U151, "YYYY-MM-DD aaa")&" ("&TEXT(W151, "hh:mm")&"~"&TEXT(X151, "hh:mm")&") : "&IF(MINUTE(Y151)=0, TEXT(Y151, "h시간"), TEXT(Y151, "h시간 m분")) -> 2025-02-19 수 (17:00~19:10) : 2시간 10분 | AB151: =_xlfn.XLOOKUP(I151, 기초데이터!$C$2:$C$305, 기초데이터!$U$2:$U$305) -> jjyoon@neurophet.com
A152: =SUBTOTAL(3,$I$2:I152)*1 -> 151 | B152: 25년 2월 | C152: 2025-02-19(17:00) ~ 2025-02-19(20:00) | D152: 1 | E152: 3.00시간 | F152: 0 | G152: AQUA팀 | H152: Team Member | I152: 강신일 | K152: 유연근무 | L152: 초과근무 | M152: 결재종결 | N152: 2025-02-20 | O152: 250219_AQUA팀_강신일 유연근무신청 | P152: 뉴로핏 주식회사-250219-AQUA팀-0002 | T152: NeuroMap Label Data Export 기능 구현 및 테스트 코드 작성, 다국어 관련 내용 추가에 따른 기능 수정 | U152: =DATEVALUE(LEFT(C152,10)) -> 45707 | V152: =WEEKNUM(U152,21) -> 8 | W152: =MID(C152,12,5) -> 17:00 | X152: =MID(C152,32,5) -> 20:00 | Y152: =X152-W152 -> 0.125 | Z152: =TEXT(U152, "YYYY-MM-DD aaa")&" ("&TEXT(W152, "hh:mm")&"~"&TEXT(X152, "hh:mm")&") : "&IF(MINUTE(Y152)=0, TEXT(Y152, "h시간"), TEXT(Y152, "h시간 m분")) -> 2025-02-19 수 (17:00~20:00) : 3시간 | AB152: =_xlfn.XLOOKUP(I152, 기초데이터!$C$2:$C$305, 기초데이터!$U$2:$U$305) -> sikang@neurophet.com
A153: =SUBTOTAL(3,$I$2:I153)*1 -> 152 | B153: 25년 2월 | C153: 2025-02-19(17:30) ~ 2025-02-19(19:30) | D153: 1 | E153: 2.00시간 | F153: 0 | G153: AD팀 | H153: Team Lead | I153: 서강희 | J153: 22060201 | K153: 유연근무 | L153: 초과근무 | M153: 결재종결 | N153: 2025-02-20 | O153: 250219 서강희 유연근무 신청 | P153: 뉴로핏 주식회사-250219-AD팀-0002 | T153: AQUA AD 3.0 NeuroEngine 적용, ARIA-E 분석 리뷰, baseline 선택 기능 구현 | U153: =DATEVALUE(LEFT(C153,10)) -> 45707 | V153: =WEEKNUM(U153,21) -> 8 | W153: =MID(C153,12,5) -> 17:30 | X153: =MID(C153,32,5) -> 19:30 | Y153: =X153-W153 -> 0.083333333 | Z153: =TEXT(U153, "YYYY-MM-DD aaa")&" ("&TEXT(W153, "hh:mm")&"~"&TEXT(X153, "hh:mm")&") : "&IF(MINUTE(Y153)=0, TEXT(Y153, "h시간"), TEXT(Y153, "h시간 m분")) -> 2025-02-19 수 (17:30~19:30) : 2시간 | AB153: =_xlfn.XLOOKUP(I153, 기초데이터!$C$2:$C$305, 기초데이터!$U$2:$U$305) -> kelly.seo@neurophet.com
A154: =SUBTOTAL(3,$I$2:I154)*1 -> 153 | B154: 25년 2월 | C154: 2025-02-19(17:35) ~ 2025-02-19(22:53) | D154: 1 | E154: 5.30시간 | F154: 0 | G154: IR팀 | H154: Team Member | I154: 유용성 | J154: 24101401 | K154: 유연근무 | L154: 초과근무 | M154: 결재종결 | N154: 2025-03-11 | O154: 202502_유용성(IR팀)_초과 근무 신청 | P154: 뉴로핏 주식회사-250311-IR팀-0001 | T154: 예심신청서, 투자기관 요청 대응 등 | U154: =DATEVALUE(LEFT(C154,10)) -> 45707 | V154: =WEEKNUM(U154,21) -> 8 | W154: =MID(C154,12,5) -> 17:35 | X154: =MID(C154,32,5) -> 22:53 | Y154: =X154-W154 -> 0.22083333 | Z154: =TEXT(U154, "YYYY-MM-DD aaa")&" ("&TEXT(W154, "hh:mm")&"~"&TEXT(X154, "hh:mm")&") : "&IF(MINUTE(Y154)=0, TEXT(Y154, "h시간"), TEXT(Y154, "h시간 m분")) -> 2025-02-19 수 (17:35~22:53) : 5시간 18분 | AB154: =_xlfn.XLOOKUP(I154, 기초데이터!$C$2:$C$305, 기초데이터!$U$2:$U$305) -> noah@neurophet.com
A155: =SUBTOTAL(3,$I$2:I155)*1 -> 154 | B155: 25년 2월 | C155: 2025-02-20(16:03) ~ 2025-02-20(17:12) | D155: 1 | E155: 1.10시간 | F155: 0 | G155: 연구기획팀 | H155: Team Member | I155: 박인영 | J155: 23082301 | K155: 유연근무 | L155: 초과근무 | M155: 결재종결 | N155: 2025-02-26 | O155: 250220_연구기획팀(박인영)_초과근무의 건 | P155: 뉴로핏 주식회사-250226-연구기획-0001 | T155: 치매극복사업 최종보고서 수정 및 제출 | U155: =DATEVALUE(LEFT(C155,10)) -> 45708 | V155: =WEEKNUM(U155,21) -> 8 | W155: =MID(C155,12,5) -> 16:03 | X155: =MID(C155,32,5) -> 17:12 | Y155: =X155-W155 -> 0.047916667 | Z155: =TEXT(U155, "YYYY-MM-DD aaa")&" ("&TEXT(W155, "hh:mm")&"~"&TEXT(X155, "hh:mm")&") : "&IF(MINUTE(Y155)=0, TEXT(Y155, "h시간"), TEXT(Y155, "h시간 m분")) -> 2025-02-20 목 (16:03~17:12) : 1시간 9분 | AB155: =_xlfn.XLOOKUP(I155, 기초데이터!$C$2:$C$305, 기초데이터!$U$2:$U$305) -> iypark@neurophet.com
...

Sheet 페이지
A2: 조회 | B2: 연월구분
A6: No | B6: 성명 | C6: 이메일 주소 | D6: 초과근무 내용 | E6: 초과근무 합
A7: 1 | B7: 하신영 | C7: sy.ha@neurophet.com | D7: 2025-02-27 목 (17:42~22:08) : 4시간 26분 2025-03-04 화 (19:07~21:47) : 2시간 40분 2025-03-05 수 (18:58~22:02) : 3시간 4분 2025-03-06 목 (18:27~22:23) : 3시간 56분 2025-03-07 금 (18:27~20:52) : 2시간 25분 2025-03-10 월 (19:04~22:09) : 3시간 5분 2025-03-11 화 (19:05~22:52) : 3시간 47분 2025-03-12 수 (19:00~21:26) : 2시간 26분 2025-03-13 목 (19:01~21:55) : 2시간 54분 2025-03-18 화 (19:23~21:49) : 2시간 26분 2025-03-21 금 (18:29~20:51) : 2시간 22분 2025-03-24 월 (18:28~21:13) : 2시간 45분 2025-03-27 목 (19:14~22:04) : 2시간 50분 | E7: 41시간 25분

Sheet 기초데이터
A1: {=_xlfn.UNIQUE([1]기초데이터!$A$3:$U$307)} -> 순서 | B1: 사번 | C1: 성명 | D1: 본부 | E1: 팀 | F1: 직무 | G1: 직위 | H1: 직책 | I1: 입사일 | J1: 정규직전환일 | K1: 고용구분 | L1: 대외제출용 인원구분 | M1: 재직상태 | N1: 주민등록번호 | O1: 생년월일 | P1: 남/여 | Q1: 나이 | R1: 만나이 | S1: 핸드폰 | T1: 주소 | U1: E-Mail
A2: 1 | B2: 16031401 | C2: 빈준길 | D2: 대표이사 | E2: 대표이사 | F2: 대표이사 | G2: Co-CEO | H2: C-LEVEL | I2: 42443 | J2: 42443 | K2: 정규직 | L2: 임원 | M2: 재직 | N2: 880328-1851618 | O2: 32230 | P2: 남 | Q2: 38 | R2: 37 | S2: 010-5004-8779 | T2: 서울특별시 영등포구 도신로29길 28, 202동 202호 | U2: jkbeen@neurophet.com
A3: 2 | B3: 16031402 | C3: 김동현 | D3: 대표이사 | E3: 연구본부 | F3: 공동대표이사 및 연구개발 총괄 | G3: Co-CEO / CTO | H3: C-LEVEL | I3: 42443 | J3: 42443 | K3: 정규직 | L3: 임원 | M3: 재직 | N3: 870721-1860421 | O3: 31979 | P3: 남 | Q3: 39 | R3: 37 | S3: 010-9361-3781 | T3: 경기도 남양주시 경춘로 859번길 17-26(금곡동) | U3: donghyeon.kim@neurophet.com
A4: 3 | B4: 17030101 | C4: 윤계현 | D4: 경영본부 | E4: 자금팀 | F4: 재무 | G4: Lead | H4: 팀리드 | I4: 42795 | J4: 42795 | K4: 정규직 | L4: 사무직 | M4: 재직 | N4: 780715-1473610 | O4: 28686 | P4: 남 | Q4: 48 | R4: 46 | S4: 010-9144-4813 | T4: 서울특별시 강동구 천호동 21-205번지 | U4: khyoon@neurophet.com
A5: 4 | B5: 17122101 | C5: 한상진 | D5: 프로덕트본부 | E5: PM팀 | F5: PM | G5: Lead | H5: 팀리드 | I5: 43090 | J5: 43090 | K5: 정규직 | L5: 연구직 | M5: 재직 | N5: 880803-1490616 | O5: 32358 | P5: 남 | Q5: 38 | R5: 36 | S5: 010-2606-0461 | T5: 서울특별시 서초구 강남대로8길 66-5 302호 | U5: sjhan@neurophet.com
A6: 5 | B6: 19020102 | C6: 김태영 | D6: 연구본부 | E6: 임상연구실 | F6: 임상연구 | G6: Director | H6: 실리드 | I6: 43507 | J6: 43507 | K6: 정규직 | L6: 연구직 | M6: 재직 | N6: 900205-2588017 | O6: 32909 | P6: 여 | Q6: 36 | R6: 35 | S6: 010-3757-8384 | T6: 경기도 용인시 수지구 포은대로 경기도 용인시 수지구 포은대로313번길 7-10 105동 3002호 | U6: ty.kim@neurophet.com
A7: 6 | B7: 20020102 | C7: 이민호 | D7: 연구본부 | E7: AR실 | F7: AI연구 | G7: Director | H7: 실리드 | I7: 43862 | J7: 43862 | K7: 정규직 | L7: 연구직 | M7: 재직 | N7: 820812-1702737 | O7: 30175 | P7: 남 | Q7: 44 | R7: 42 | S7: 010-2780-2180 | T7: 경기도 고양시 일산서구 덕산로 277-4, 아펠리움 101동 301호 | U7: minho.lee@neurophet.com
A8: 7 | B8: 20030103 | C8: 이창훈 | D8: 프로덕트본부 | E8: 개발1실 | F8: 개발 | G8: Director | H8: 실리드 | I8: 43891 | J8: 43891 | K8: 정규직 | L8: 연구직 | M8: 재직 | N8: 750223-1403514 | O8: 27417 | P8: 남 | Q8: 51 | R8: 50 | S8: 010-2744-4757 | T8: 서울특별시 강동구 양재대로 1706(아남아파트) 8동 1804호 | U8: leech.lee@neurophet.com
A9: 8 | B9: 20030106 | C9: 허진이 | D9: 대표이사 | E9: 인사팀 | F9: 인사 | G9: Member | H9: 멤버 | I9: 43891 | J9: 43891 | K9: 정규직 | L9: 사무직 | M9: 재직 | N9: 981117-2474420 | O9: 36116 | P9: 여 | Q9: 28 | R9: 26 | S9: 010-5592-1057 | T9: 서울특별시 마포구 토정로 31길 24 마포리버파크 109동 402호 | U9: jiniheo@neurophet.com
A10: 9 | B10: 20031201 | C10: 경채윤 | D10: 프로덕트본부 | E10: SCM팀 | F10: 생산관리 | G10: Member | H10: 멤버 | I10: 43902 | J10: 43902 | K10: 정규직 | L10: 연구직 | M10: 재직 | N10: 890320-2214115 | O10: 32587 | P10: 여 | Q10: 37 | R10: 36 | S10: 010-5049-7358 | T10: 경기도 화성시 영통로 61번길 10 신영통현대 1단지 103동 1003호 | U10: cykyung@neurophet.com
A11: 10 | B11: 20051801 | C11: 김은영 | D11: 연구본부 | E11: NI실 | F11: 뇌영상분석연구 | G11: Director | H11: 실리드 | I11: 43969 | J11: 43969 | K11: 정규직 | L11: 연구직 | M11: 재직 | N11: 820111-2024619 | O11: 29962 | P11: 여 | Q11: 44 | R11: 43 | S11: 010-4022-3152 | T11: 서울특별시 강남구 개포로310, 148동 2304호 | U11: reginaeunyoungkim@neurophet.com
A12: 11 | B12: 20062901 | C12: 류준환 | D12: 연구본부 | E12: AR1팀 | F12: AI연구 | G12: Lead | H12: 팀리드 | I12: 44011 | J12: 44011 | K12: 정규직 | L12: 연구직 | M12: 재직 | N12: 891019-1047818 | O12: 32800 | P12: 남 | Q12: 37 | R12: 35 | S12: 010-6229-1650 | T12: 경기도 성남시 분당구 정자2동 한솔마을 4단지 415 - 1801호 | U12: clarence@neurophet.com
A13: 12 | B13: 20070103 | C13: 송단비 | D13: 연구본부 | E13: 임상팀 | F13: 임상연구 | G13: Lead | H13: 팀리드 | I13: 44013 | J13: 44013 | K13: 정규직 | L13: 연구직 | M13: 재직 | N13: 880503-2408617 | O13: 32266 | P13: 여 | Q13: 38 | R13: 36 | S13: 010-9053-1523 | T13: 서울특별시 송파구 백제고분로12길 3-22 302호 | U13: dbsong@neurophet.com
... A228: 227 | B228: 21020101 | C228: 손명수 | D228: 프로덕트본부 | E228: Frontend팀 | F228: Front_End개발 | G228: Member | H228: 멤버 | I228: 44228 | J228: 44228 | K228: 정규직 | L228: 연구직 | M228: 퇴직 | N228: 960830-1167725 | O228: 35307 | P228: 남 | Q228: 30 | R228: 28 | S228: 010-6282-3838 | T228: 경기도 성남시 수정구 남문로 69번길 5-10 | U228: msson@neurophet.com
A229: 228 | B229: 22020703 | C229: 백성인 | D229: 연구본부 | E229: 임상연구팀 | F229: 임상시험 | G229: Temporary | H229: 계약직 | I229: 44599 | J229: 44599 | K229: 계약직 | L229: 사무직 | M229: 퇴직 | N229: 980410-1524919 | O229: 35895 | P229: 남 | Q229: 28 | R229: 26 | S229: 010-2539-4706 | T229: 서울특별시 은평구 불광로22길 16 (대신리젠츠) 201호 | U229: 0
A230: 229 | B230: 22070401 | C230: 우상아 | D230: 연구본부 | E230: TechOps팀 | F230: 데이터검수 | G230: Temporary | H230: 계약직 | I230: 44746 | J230: 44746 | K230: 계약직 | L230: 사무직 | M230: 퇴직 | N230: 930412-2164011 | O230: 34071 | P230: 여 | Q230: 33 | R230: 31 | S230: 010-5721-1370 | T230: 경기도 수원시 장안구 파장천로66번길 106-9 304호 | U230: sangah@neurophet.com
A231: 230 | B231: 20030102 | C231: 변종원 | D231: 프로덕트본부 | E231: Backend팀 | F231: 서버개발 | G231: Member | H231: 멤버 | I231: 43891 | J231: 43891 | K231: 정규직 | L231: 연구직 | M231: 퇴직 | N231: 701001-1029429 | O231: 25842 | P231: 남 | Q231: 56 | R231: 54 | S231: 010-5040-0011 | T231: 경기도 고양시 일산동구 중산로 206 (중산동, 중산마을) 704동 403호 | U231: martin.byun@neurophet.com
A232: 231 | B232: 20070101 | C232: 이국행 | D232: 프로덕트본부 | E232: Backend팀 | F232: 서버개발 | G232: Member | H232: 멤버 | I232: 44013 | J232: 44013 | K232: 정규직 | L232: 연구직 | M232: 퇴직 | N232: 740925-1654910 | O232: 27297 | P232: 남 | Q232: 52 | R232: 50 | S232: 010-5472-5956 | T232: 서울특별시 강동구 아리수로 50길 50, 102동 302호 | U232: khlee@neurophet.com
A233: 232 | B233: 20070102 | C233: 권혜은 | D233: 프로덕트본부 | E233: Backend팀 | F233: 서버개발 | G233: Member | H233: 멤버 | I233: 44013 | J233: 44013 | K233: 정규직 | L233: 연구직 | M233: 퇴직 | N233: 770125-2812415 | O233: 28150 | P233: 여 | Q233: 49 | R233: 48 | S233: 010-2012-5023 | T233: 서울특별시 노원구 섬밭로 123 301-1406 | U233: hyeeun@neurophet.com
A234: 233 | B234: 21121301 | C234: 조성자 | D234: 연구본부 | E234: 의학팀 | F234: Medical Direct | G234: Member | H234: 멤버 | I234: 44543 | J234: 44543 | K234: 정규직 | L234: 연구직 | M234: 퇴직 | N234: 640603-2068715 | O234: 23531 | P234: 여 | Q234: 62 | R234: 60 | S234: 010-5311-6804 | T234: 서울특별시 관악구 관악로 263 관악브라운스톤 102동 302호 | U234: sungjacho@neurophet.com
A235: 234 | B235: 21090101 | C235: 변인철 | D235: 비즈니스본부 | E235: 세일즈팀 | F235: 영업 | G235: Lead | H235: 팀리드 | I235: 44440 | J235: 44440 | K235: 정규직 | L235: 사무직 | M235: 퇴직 | N235: 830102-1928212 | O235: 30318 | P235: 남 | Q235: 43 | R235: 42 | S235: 010-2042-7898 | T235: 서울특별시 마포구 상암동 월드컵파크4단지 401동402호 | U235: icbyun@neurophet.com
A236: 235 | B236: 20030104 | C236: 백선우 | D236: 비즈니스본부 | E236: 세일즈팀 | F236: 영업 | G236: Member | H236: 멤버 | I236: 43891 | J236: 43891 | K236: 정규직 | L236: 사무직 | M236: 퇴직 | N236: 820125-1226710 | O236: 29976 | P236: 남 | Q236: 44 | R236: 43 | S236: 010-4525-2187 | T236: 경기도 고양시 일산서구 일산로 488 후곡13단지 1301동 207호 | U236: sunwoo.paek@neurophet.com
A237: 236 | B237: 21091304 | C237: 임창대 | D237: 연구본부 | E237: TechOps팀 | F237: 데이터검수 | G237: Temporary | H237: 계약직 | I237: 44452 | J237: 44452 | K237: 계약직 | L237: 사무직 | M237: 퇴직 | N237: 981201-1330919 | O237: 36130 | P237: 남 | Q237: 28 | R237: 26 | S237: 010-3191-1146 | T237: 서울특별시 중랑구 면목로80길6 400호(면목동,씨티플러스) | U237: changdae.yim@neurophet.com
A238: 237 | B238: 22032101 | C238: 유지영 | D238: 연구본부 | E238: TechOps팀 | F238: 데이터검수 | G238: Temporary | H238: 계약직 | I238: 44641 | J238: 44641 | K238: 계약직 | L238: 사무직 | M238: 퇴직 | N238: 961017-2051125 | O238: 35355 | P238: 여 | Q238: 30 | R238: 28 | S238: 010-2734-2881 | T238: 서울특별시 은평구 진흥로 84-1 태경쉐르빌 501호 | U238: jiyeong.yoo@neurophet.com
A239: 238 | B239: 22040402 | C239: 전은실 | D239: 연구본부 | E239: TechOps팀 | F239: 데이터검수 | G239: Temporary | H239: 계약직 | I239: 44655 | J239: 44655 | K239: 계약직 | L239: 사무직 | M239: 퇴직 | N239: 980810-2018114 | O239: 36017 | P239: 여 | Q239: 28 | R239: 26 | S239: 010-4943-0992 | T239: 경기도 양주시 삼숭로58번길 141 자이아파트 707동 1203호 | U239: eunsil.jeon@neurophet.com
A240: 239 | B240: 22041103 | C240: 이재혁 | D240: 연구본부 | E240: TechOps팀 | F240: 데이터검수 | G240: Temporary | H240: 계약직 | I240: 44662 | J240: 44662 | K240: 계약직 | L240: 사무직 | M240: 퇴직 | N240: 000321-3409913 | O240: 36606 | P240: 남 | Q240: 26 | R240: 25 | S240: 010-2950-4757 | T240: 서울특별시 강동구 양재대로 1706, 8동 1804호 | U240: jaehyuk.lee@neurophet.com
A241: 240 | B241: 22040401 | C241: 이준혁 | D241: 연구본부 | E241: TechOps팀 | F241: 데이터검수 | G241: Temporary | H241: 계약직 | I241: 44655 | J241: 44655 | K241: 계약직 | L241: 사무직 | M241: 퇴직 | N241: 980705-1816718 | O241: 35981 | P241: 남 | Q241: 28 | R241: 26 | S241: 010-9676-1715 | T241: 서울특별시 도봉구 도봉로109가길 5 301호 | U241: junhyeok.lee@neurophet.com
... A244: 243 | B244: 20030101 | C244: 박재형 | D244: 비즈니스본부 | E244: 비즈니스본부 | F244: CBO | G244: CBO | H244: C-LEVEL | I244: 43891 | J244: 43891 | K244: 정규직 | L244: 사무직 | M244: 퇴직 | N244: 740325-1080719 | O244: 27113 | P244: 남 | Q244: 52 | R244: 51 | S244: 010-5260-7632 | T244: 서울특별시 동작구 노량진동 332번지 쌍용예가 101-102 | U244: jh.park@neurophet.com
A245: 244 | B245: 21091303 | C245: 김은비 | D245: 연구본부 | E245: TechOps팀 | F245: 레이블링 | G245: Temporary | H245: 계약직 | I245: 44452 | J245: 44452 | K245: 계약직 | L245: 사무직 | M245: 퇴직 | N245: 980608-2194618 | O245: 35954 | P245: 여 | Q245: 28 | R245: 26 | S245: 0 | T245: 경기 안양시 동안구 일동로 172, 202호 | U245: 0
A246: 245 | B246: 21120101 | C246: 김승환 | D246: 비즈니스본부 | E246: 마케팅팀 | F246: 마케팅 | G246: Member | H246: 멤버 | I246: 44531 | J246: 44531 | K246: 정규직 | L246: 사무직 | M246: 퇴직 | N246: 830106-1169811 | O246: 30322 | P246: 남 | Q246: 43 | R246: 42 | S246: 010-9925-2244 | T246: 경기도 성남시 수정구 위례광장로 97 위례자연앤센트럴자이 3202동 403호 | U246: shkim@neurophet.com
A247: 246 | B247: 20072701 | C247: 한재우 | D247: 프로덕트본부 | E247: Frontend팀 | F247: Front_End개발 | G247: Member | H247: 멤버 | I247: 44039 | J247: 44039 | K247: 정규직 | L247: 연구직 | M247: 퇴직 | N247: 891012-1408216 | O247: 32793 | P247: 남 | Q247: 37 | R247: 35 | S247: 010-4819-1012 | T247: 서울시 양천구 목동동로 50 1220동 903호 | U247: jaewoo.han@neurophet.com
A248: 247 | B248: 21101401 | C248: 김원정 | D248: 연구본부 | E248: 임상연구팀 | F248: 임상연구지원 | G248: Temporary | H248: 계약직 | I248: 44483 | J248: 44483 | K248: 계약직 | L248: 사무직 | M248: 퇴직 | N248: 880810-2081614 | O248: 32365 | P248: 여 | Q248: 38 | R248: 36 | S248: 0 | T248: 서울시 강동구 천호옉14길 | U248: 0
A249: 248 | B249: 18020101 | C249: 김다연 | D249: 경영본부 | E249: 재무팀 | F249: 재무 | G249: Member | H249: 멤버 | I249: 43132 | J249: 43132 | K249: 정규직 | L249: 사무직 | M249: 퇴직 | N249: 900416-2158313 | O249: 32979 | P249: 여 | Q249: 36 | R249: 34 | S249: 010-9557-5460 | T249: 인천시 남동구 서창남순환로 190-100, 604동 1702호 | U249: dykim@neurophet.com
A250: 249 | B250: 20122101 | C250: 홍서연 | D250: 프로덕트본부 | E250: QA팀 | F250: QC | G250: Member | H250: 멤버 | I250: 44186 | J250: 44186 | K250: 정규직 | L250: 연구직 | M250: 퇴직 | N250: 931012-2184534 | O250: 34254 | P250: 여 | Q250: 33 | R250: 31 | S250: 010-6291-0179 | T250: 경기도 부천시 소사구 안곡로4 209-807 | U250: syhong@neurophet.com
A251: 250 | B251: 20122102 | C251: 신윤하 | D251: 연구본부 | E251: Neuroimaging팀 | F251: 신경망 | G251: Member | H251: 멤버 | I251: 44186 | J251: 44186 | K251: 정규직 | L251: 연구직 | M251: 퇴직 | N251: 880510-2055628 | O251: 32273 | P251: 여 | Q251: 38 | R251: 36 | S251: 010-9122-8339 | T251: 서울특별시 영등포구 선유동2로 56 205동 1105호 | U251: eyshin@neurophet.com
A252: 251 | B252: 21090601 | C252: 남혜령 | D252: 연구본부 | E252: Neuroimaging팀 | F252: 신경망 | G252: Member | H252: 멤버 | I252: 44445 | J252: 44445 | K252: 정규직 | L252: 연구직 | M252: 퇴직 | N252: 900617-2183113 | O252: 33041 | P252: 여 | Q252: 36 | R252: 34 | S252: 010-2255-2728 | T252: 경기도 안산시 사세충열로 4길 19 꿈애그린빌 A동 401호 | U252: hrnam@neurophet.com
A253: 252 | B253: 20051101 | C253: 고봉석 | D253: 연구본부 | E253: Neuroengineering | F253: Planning | G253: Member | H253: 멤버 | I253: 43962 | J253: 43962 | K253: 정규직 | L253: 연구직 | M253: 퇴직 | N253: 930705-1019014 | O253: 34155 | P253: 남 | Q253: 33 | R253: 31 | S253: 010-2573-5546 | T253: 경기도 성남시 궁내동 궁내로 7번길 14 동양파크타운 111동 203호 | U253: bsko@neurophet.com
A254: 253 | B254: 20020101 | C254: 김대희 | D254: 프로덕트본부 | E254: 개발팀 | F254: 개발총괄 | G254: Director | H254: 멤버 | I254: 43862 | J254: 43862 | K254: 정규직 | L254: 연구직 | M254: 퇴직 | N254: 721223-1785418 | O254: 26656 | P254: 남 | Q254: 54 | R254: 52 | S254: 010-8255-1053 | T254: 경기도 부천시 중동로 64, 105동 503호(송내동, 부천중동역푸르지오아파트) | U254: dh.kim@neurophet.com
A255: 254 | B255: 21050301 | C255: 김지호 | D255: 프로덕트본부 | E255: QA팀 | F255: QA | G255: Lead | H255: 멤버 | I255: 44319 | J255: 44319 | K255: 정규직 | L255: 연구직 | M255: 퇴직 | N255: 860703-1561418 | O255: 31596 | P255: 남 | Q255: 40 | R255: 38 | S255: 0 | T255: 경기도 안양시 동안구 시민대로 266 (관양동, 평촌샤르망오피스텔) 1327호 | U255: 0
A256: 255 | B256: 21102501 | C256: 장진원 | D256: 사업개발본부 | E256: 사업개발본부 | F256: 해외사업 | G256: Member | H256: 멤버 | I256: 44494 | J256: 44494 | K256: 정규직 | L256: 사무직 | M256: 퇴직 | N256: 810907-5100138 | O256: 29836 | P256: 남 | Q256: 45 | R256: 43 | S256: 010-2071-4447 | T256: 서울특별시 용산구 원효로 63길 22 201호 | U256: jwjang@neurophet.com
...
